<?xml version="1.0" ?>
<sdf version="1.5">
    <model name="turtlebot3_burger">
        <link name="base">
            <inertial>
                <pose>-0.032 0 0.070 0 0 0</pose>
                <inertia>
                    <ixx>0.001</ixx>
                    <ixy>0.000</ixy>
                    <ixz>0.000</ixz>
                    <iyy>0.001</iyy>
                    <iyz>0.000</iyz>
                    <izz>0.001</izz>
                </inertia>
                <mass>1.0</mass>
            </inertial>
            <collision name="base_collision">
                <pose>-0.032 0 0.070 0 0 0</pose>
                <geometry>
                    <box>
                        <size>0.140 0.140 0.140</size>
                    </box>
                </geometry>
            </collision>
            <visual name="base_visual">
                <pose>-0.032 0 0 0 0 0</pose>
                <geometry>
                    <mesh>
                        <uri>meshes/burger_base.stl</uri>
                        <scale>.001 .001 .001</scale>
                    </mesh>
                </geometry>
                <material>
                    <ambient>0.9 0.1 0 1</ambient>
                    <diffuse>0.9 0.1 0 1</diffuse>
                    <specular>0.9 0.2 0.2 1</specular>
                    <emissive>0.9 0 0.1 1</emissive>
                </material>
            </visual>
            <collision name="caster_collision">
                <pose>-0.081 0 -0.004 0 0 0</pose>
                <geometry>
                    <sphere>
                        <radius>0.005000</radius>
                    </sphere>
                </geometry>
                <surface>
                    <friction>
                        <ode>
                            <mu>0.1</mu>
                            <mu2>0.1</mu2>
                            <fdir1>0 0 0</fdir1>
                            <slip1>0</slip1>
                            <slip2>0</slip2>
                        </ode>
                    </friction>
                </surface>
            </collision>
        </link>
        <link name="lidar">
            <inertial>
                <pose>-0.020 0 0.161 0 0 0</pose>
                <inertia>
                    <ixx>0.001</ixx>
                    <ixy>0.000</ixy>
                    <ixz>0.000</ixz>
                    <iyy>0.001</iyy>
                    <iyz>0.000</iyz>
                    <izz>0.001</izz>
                </inertia>
                <mass>0.125</mass>
            </inertial>
            <collision name="lidar_sensor_collision">
                <pose>-0.020 0 0.161 0 0 0</pose>
                <geometry>
                    <cylinder>
                        <radius>0.0508</radius>
                        <length>0.055</length>
                    </cylinder>
                </geometry>
            </collision>
            <visual name="lidar_sensor_visual">
                <pose>-0.032 0 0.171 0 0 0</pose>
                <geometry>
                    <mesh>
                        <uri>meshes/lds.stl</uri>
                        <scale>0.001 0.001 0.001</scale>
                    </mesh>
                </geometry>
                <material>
                    <ambient>0.5 0.75 0 1</ambient>
                    <diffuse>0.7 0.9 0 1</diffuse>
                    <specular>0.2 0.2 0.2 1</specular>
                    <emissive>0.1 0 0.1 1</emissive>
                </material>
            </visual>
            <sensor name="lidar" type="gpu_lidar">
                <pose>-0.020 0 0.161 0 0 0</pose>
                <topic>/scan</topic>
                <update_rate>10</update_rate>
                <lidar>
                    <scan>
                        <horizontal>
                            <samples>360</samples>
                            <resolution>1</resolution>
                            <min_angle>-3.14159</min_angle>
                            <max_angle>3.14159</max_angle>
                        </horizontal>
                    </scan>
                    <range>
                        <min>0.12</min>
                        <max>3.5</max>
                        <resolution>0.01</resolution>
                    </range>
                    <noise>
                        <type>gaussian</type>
                        <mean>0</mean>
                        <stddev>0.01</stddev>
                    </noise>
                </lidar>
                <always_on>1</always_on>
                <visualize>true</visualize>
            </sensor>
        </link>
        <link name="left_wheel">
            <inertial>
                <pose>0 0.08 0.023 -1.57 0 0</pose>
                <inertia>
                    <ixx>0.001</ixx>
                    <ixy>0.000</ixy>
                    <ixz>0.000</ixz>
                    <iyy>0.001</iyy>
                    <iyz>0.000</iyz>
                    <izz>0.001</izz>
                </inertia>
                <mass>0.1</mass>
            </inertial>
            <collision name="left_wheel_collision">
                <pose>0 0.08 0.023 -1.57 0 0</pose>
                <geometry>
                    <cylinder>
                        <radius>0.033</radius>
                        <length>0.018</length>
                    </cylinder>
                </geometry>
                <surface>
                    <!-- This friction pamareter don't contain reliable data!! -->
                    <friction>
                        <ode>
                            <mu>100000.0</mu>
                            <mu2>100000.0</mu2>
                            <fdir1>0 0 0</fdir1>
                            <slip1>0.0</slip1>
                            <slip2>0.0</slip2>
                        </ode>
                    </friction>
                </surface>
            </collision>
            <visual name="left_wheel_visual">
                <pose>0 0.08 0.023 0 0 0</pose>
                <geometry>
                    <mesh>
                        <uri>meshes/left_tire.stl</uri>
                        <scale>0.001 0.001 0.001</scale>
                    </mesh>
                </geometry>
                <material>
                    <ambient>0.1 0.1 0.1 1</ambient>
                    <diffuse>0.1 0.1 0.1 1</diffuse>
                    <specular>0.1 0.1 0.1 1</specular>
                    <emissive>0.1 0.1 0.1 1</emissive>
                </material>
            </visual>
        </link>
        <link name="right_wheel">
            <inertial>
                <pose>0.0 -0.08 0.023 -1.57 0 0</pose>
                <inertia>
                    <ixx>0.001</ixx>
                    <ixy>0.000</ixy>
                    <ixz>0.000</ixz>
                    <iyy>0.001</iyy>
                    <iyz>0.000</iyz>
                    <izz>0.001</izz>
                </inertia>
                <mass>0.1</mass>
            </inertial>
            <collision name="right_wheel_collision">
                <pose>0.0 -0.08 0.023 -1.57 0 0</pose>
                <geometry>
                    <cylinder>
                        <radius>0.033</radius>
                        <length>0.018</length>
                    </cylinder>
                </geometry>
                <surface>
                    <!-- This friction pamareter don't contain reliable data!! -->
                    <friction>
                        <ode>
                            <mu>100000.0</mu>
                            <mu2>100000.0</mu2>
                            <fdir1>0 0 0</fdir1>
                            <slip1>0.0</slip1>
                            <slip2>0.0</slip2>
                        </ode>
                    </friction>
                </surface>
            </collision>
            <visual name="right_wheel_visual">
                <pose>0.0 -0.08 0.023 0 0 0</pose>
                <geometry>
                    <mesh>
                        <uri>meshes/right_tire.stl</uri>
                        <scale>0.001 0.001 0.001</scale>
                    </mesh>
                </geometry>
                <material>
                    <ambient>0.1 0.1 0.1 1</ambient>
                    <diffuse>0.1 0.1 0.1 1</diffuse>
                    <specular>0.1 0.1 0.1 1</specular>
                    <emissive>0.1 0.1 0.1 1</emissive>
                </material>
            </visual>
        </link>
        <joint name="left_wheel_joint" type="revolute">
            <parent>base</parent>
            <child>left_wheel</child>
            <pose>0.0 0.08 0.023 -1.57 0 0</pose>
            <axis>
                <xyz>0 0 1</xyz>
            </axis>
        </joint>
        <joint name="right_wheel_joint" type="revolute">
            <parent>base</parent>
            <child>right_wheel</child>
            <pose>0.0 -0.08 0.023 -1.57 0 0</pose>
            <axis>
                <xyz>0 0 1</xyz>
            </axis>
        </joint>
        <joint name="lidar_joint" type="fixed">
            <parent>base</parent>
            <child>lidar</child>
            <pose>-0.032 0 0.171 0 0 0</pose>
            <axis>
                <xyz>0 0 1</xyz>
                <use_parent_model_frame>true</use_parent_model_frame>
            </axis>
        </joint>
        <!-- DIFF DRIVE PLUGIN / WHEELS CONTROLER -->
        <plugin filename="gz-sim-diff-drive-system" name="gz::sim::systems::DiffDrive">
    	    <left_joint>left_wheel_joint</left_joint>
            <right_joint>right_wheel_joint</right_joint>
            <wheel_separation>0.160</wheel_separation>
            <wheel_radius>0.033</wheel_radius>
            <odom_publish_frequency>20</odom_publish_frequency>
            <topic>/cmd_vel</topic>
            <odom_topic>/odom</odom_topic>
            <frame_id>odom</frame_id>
            <child_frame_id>base_link</child_frame_id>
        </plugin>
        <static>0</static>
    </model>
</sdf>
